<?xml version="1.0" encoding="UTF-8"?>
<!-- Generated by org.testng.reporters.JUnitReportReporter -->
<testsuite skipped="0" hostname="RakeshPC" name="com.M4.NewTest" tests="12" failures="1" timestamp="21 Jan 2018 09:11:10 GMT" time="0.016" errors="1">
  <testcase name="isPositive" time="0.000" classname="com.M4.NewTest"/>
  <testcase name="multiplyingNumbers" time="0.000" classname="com.M4.NewTest"/>
  <testcase name="cosine" time="0.000" classname="com.M4.NewTest">
    <failure type="java.lang.AssertionError" message="expected [1.0] but found [0.0]">
      <![CDATA[java.lang.AssertionError: expected [1.0] but found [0.0]at org.testng.Assert.fail(Assert.java:96)at org.testng.Assert.failNotEquals(Assert.java:776)at org.testng.Assert.assertEqualsImpl(Assert.java:137)at org.testng.Assert.assertEquals(Assert.java:118)at org.testng.Assert.assertEquals(Assert.java:442)at com.M4.NewTest.cosine(NewTest.java:128)at sun.reflect.NativeMethodAccessorImpl.invoke0(Native Method)at sun.reflect.NativeMethodAccessorImpl.invoke(NativeMethodAccessorImpl.java:62)at sun.reflect.DelegatingMethodAccessorImpl.invoke(DelegatingMethodAccessorImpl.java:43)at java.lang.reflect.Method.invoke(Method.java:498)at org.testng.internal.MethodInvocationHelper.invokeMethod(MethodInvocationHelper.java:124)at org.testng.internal.Invoker.invokeMethod(Invoker.java:571)at org.testng.internal.Invoker.invokeTestMethod(Invoker.java:707)at org.testng.internal.Invoker.invokeTestMethods(Invoker.java:979)at org.testng.internal.TestMethodWorker.invokeTestMethods(TestMethodWorker.java:125)at org.testng.internal.TestMethodWorker.run(TestMethodWorker.java:109)at org.testng.TestRunner.privateRun(TestRunner.java:648)at org.testng.TestRunner.run(TestRunner.java:505)at org.testng.SuiteRunner.runTest(SuiteRunner.java:455)at org.testng.SuiteRunner.runSequentially(SuiteRunner.java:450)at org.testng.SuiteRunner.privateRun(SuiteRunner.java:415)at org.testng.SuiteRunner.run(SuiteRunner.java:364)at org.testng.SuiteRunnerWorker.runSuite(SuiteRunnerWorker.java:52)at org.testng.SuiteRunnerWorker.run(SuiteRunnerWorker.java:84)at org.testng.TestNG.runSuitesSequentially(TestNG.java:1187)at org.testng.TestNG.runSuitesLocally(TestNG.java:1116)at org.testng.TestNG.runSuites(TestNG.java:1028)at org.testng.TestNG.run(TestNG.java:996)at com.M4.RunProgrammatically.main(RunProgrammatically.java:22)]]>
    </failure>
  </testcase> <!-- cosine -->
  <testcase name="multiplyingNumbers" time="0.000" classname="com.M4.NewTest"/>
  <testcase name="divideByZero" time="0.000" classname="com.M4.NewTest"/>
  <testcase name="multiplyingNumbers" time="0.000" classname="com.M4.NewTest"/>
  <testcase name="divideZerobyANumber" time="0.000" classname="com.M4.NewTest"/>
  <testcase name="addingTwoPositiveNumbers" time="0.016" classname="com.M4.NewTest"/>
  <testcase name="subtractingTwoNumbers" time="0.000" classname="com.M4.NewTest"/>
  <testcase name="isNegative" time="0.000" classname="com.M4.NewTest"/>
  <testcase name="multiplyingNumbers" time="0.000" classname="com.M4.NewTest"/>
  <testcase name="squareRootOfNegativeNumber" time="0.000" classname="com.M4.NewTest">
    <error type="org.testng.TestException" message="
Expected exception of type class java.lang.NumberFormatException but got java.lang.AssertionError: expected [2.23606797749979] but found [5.0]">
      <![CDATA[org.testng.TestException: Expected exception of type class java.lang.NumberFormatException but got java.lang.AssertionError: expected [2.23606797749979] but found [5.0]at org.testng.internal.ExpectedExceptionsHolder.wrongException(ExpectedExceptionsHolder.java:68)at org.testng.internal.Invoker.considerExceptions(Invoker.java:1120)at org.testng.internal.Invoker.invokeMethod(Invoker.java:603)at org.testng.internal.Invoker.invokeTestMethod(Invoker.java:707)at org.testng.internal.Invoker.invokeTestMethods(Invoker.java:979)at org.testng.internal.TestMethodWorker.invokeTestMethods(TestMethodWorker.java:125)at org.testng.internal.TestMethodWorker.run(TestMethodWorker.java:109)at org.testng.TestRunner.privateRun(TestRunner.java:648)at org.testng.TestRunner.run(TestRunner.java:505)at org.testng.SuiteRunner.runTest(SuiteRunner.java:455)at org.testng.SuiteRunner.runSequentially(SuiteRunner.java:450)at org.testng.SuiteRunner.privateRun(SuiteRunner.java:415)at org.testng.SuiteRunner.run(SuiteRunner.java:364)at org.testng.SuiteRunnerWorker.runSuite(SuiteRunnerWorker.java:52)at org.testng.SuiteRunnerWorker.run(SuiteRunnerWorker.java:84)at org.testng.TestNG.runSuitesSequentially(TestNG.java:1187)at org.testng.TestNG.runSuitesLocally(TestNG.java:1116)at org.testng.TestNG.runSuites(TestNG.java:1028)at org.testng.TestNG.run(TestNG.java:996)at com.M4.RunProgrammatically.main(RunProgrammatically.java:22)Caused by: java.lang.AssertionError: expected [2.23606797749979] but found [5.0]at org.testng.Assert.fail(Assert.java:96)at org.testng.Assert.failNotEquals(Assert.java:776)at org.testng.Assert.assertEqualsImpl(Assert.java:137)at org.testng.Assert.assertEquals(Assert.java:118)at org.testng.Assert.assertEquals(Assert.java:442)at com.M4.NewTest.squareRootOfNegativeNumber(NewTest.java:119)at sun.reflect.NativeMethodAccessorImpl.invoke0(Native Method)at sun.reflect.NativeMethodAccessorImpl.invoke(NativeMethodAccessorImpl.java:62)at sun.reflect.DelegatingMethodAccessorImpl.invoke(DelegatingMethodAccessorImpl.java:43)at java.lang.reflect.Method.invoke(Method.java:498)at org.testng.internal.MethodInvocationHelper.invokeMethod(MethodInvocationHelper.java:124)at org.testng.internal.Invoker.invokeMethod(Invoker.java:571)... 17 more]]>
    </error>
  </testcase> <!-- squareRootOfNegativeNumber -->
</testsuite> <!-- com.M4.NewTest -->
